Workbook

Sheet Dashboard
A1: MAJOR GIFTS & MOVES MANAGEMENT TOOLKIT
A2: Module 3: Major Gifts | Build Your Club Nonprofit Fundraising Course
A4: ORGANIZATION INFORMATION
A5: Organization Name: | D5: Fiscal Year:
A6: Major Gift Threshold: $ | D6: Development Officer:
A7: Date Updated:
A9: MAJOR GIFT PIPELINE SUMMARY
A10: ℹ Counts auto-populate from the Moves Management sheet (column D = Stage). Update that sheet to refresh.
A11: Stage | B11: # Prospects | C11: % of Pipeline | D11: Total Ask Value ($) | E11: Avg Ask ($) | F11: Notes
A12: Identification | B12: =COUNTIF('Moves Management'!D:D,"Identification") -> 1 | C12: =IF(B19=0,"-",B12/B19) -> 0.14285714 | D12: =SUMIF('Moves Management'!D:D,"Identification",'Moves Management'!H:H) -> 5 | E12: =IF(B12=0,"-",D12/B12) -> 5 | F12: Initial list — not yet researched
A13: Research | B13: =COUNTIF('Moves Management'!D:D,"Research") -> 1 | C13: =IF(B19=0,"-",B13/B19) -> 0.14285714 | D13: =SUMIF('Moves Management'!D:D,"Research",'Moves Management'!H:H) -> 3 | E13: =IF(B13=0,"-",D13/B13) -> 3 | F13: Background research underway
A14: Cultivation | B14: =COUNTIF('Moves Management'!D:D,"Cultivation") -> 3 | C14: =IF(B19=0,"-",B14/B19) -> 0.42857143 | D14: =SUMIF('Moves Management'!D:D,"Cultivation",'Moves Management'!H:H) -> 22 | E14: =IF(B14=0,"-",D14/B14) -> 7.3333333 | F14: Active moves being executed
A15: Solicitation Ready | B15: =COUNTIF('Moves Management'!D:D,"Solicitation Ready") -> 1 | C15: =IF(B19=0,"-",B15/B19) -> 0.14285714 | D15: =SUMIF('Moves Management'!D:D,"Solicitation Ready",'Moves Management'!H:H) -> 10 | E15: =IF(B15=0,"-",D15/B15) -> 10 | F15: Ready to ask — plan it now
A16: Proposal Submitted | B16: =COUNTIF('Moves Management'!D:D,"Proposal Submitted") -> 0 | C16: =IF(B19=0,"-",B16/B19) -> 0 | D16: =SUMIF('Moves Management'!D:D,"Proposal Submitted",'Moves Management'!H:H) -> 0 | E16: =IF(B16=0,"-",D16/B16) -> - | F16: Awaiting decision
A17: Gift Received | B17: =COUNTIF('Moves Management'!D:D,"Gift Received") -> 0 | C17: =IF(B19=0,"-",B17/B19) -> 0 | D17: =SUMIF('Moves Management'!D:D,"Gift Received",'Moves Management'!H:H) -> 0 | E17: =IF(B17=0,"-",D17/B17) -> - | F17: Gift closed this period
A18: Stewardship | B18: =COUNTIF('Moves Management'!D:D,"Stewardship") -> 1 | C18: =IF(B19=0,"-",B18/B19) -> 0.14285714 | D18: =SUMIF('Moves Management'!D:D,"Stewardship",'Moves Management'!H:H) -> 8 | E18: =IF(B18=0,"-",D18/B18) -> 8 | F18: Executing post-gift stewardship plan
A19: TOTAL PIPELINE | B19: =SUM(B12:B18) -> 7 | C19: 100% | D19: =SUM(D12:D18) -> 48 | E19: =IF(B19=0,"-",D19/B19) -> 6.8571429
A21: KEY PERFORMANCE INDICATORS
A22: KPI | B22: Current | C22: Target | D22: Status | E22: Benchmark Notes
A23: Major Gifts Revenue YTD ($) | E23: Enter total closed major gift revenue this year
A24: Annual Major Gift Goal ($) | E24: Enter annual major gift revenue target
A25: % of Goal Achieved | B25: =IF(B24=0,"-",B23/B24) -> - | C25: 100% | E25: Auto-calc when rows above are filled
A26: # Prospects in Active Cultivation | B26: =COUNTIF('Moves Management'!D:D,"Cultivation") -> 3 | C26: 20–50 | E26: Per MGO; 100–150 in larger shops
A27: # Solicitation-Ready Prospects | B27: =COUNTIF('Moves Management'!D:D,"Solicitation Ready") -> 1 | C27: 5–10 | E27: Always have asks in the pipeline
A28: Proposals Outstanding | B28: =COUNTIF('Proposal Tracker'!G:G,"Submitted")+COUNTIF('Proposal Tracker'!G:G,"Under Consideration") -> 3 | E28: From Proposal Tracker sheet
A29: Avg. Major Gift Size ($) | E29: Total revenue ÷ # of gifts
A30: Prospects Overdue (90-day rule) | B30: =COUNTIF('Moves Management'!M:M,"OVERDUE") -> 0 | C30: 0 | E30: Zero tolerance — act on any flagged prospects immediately
A31: Major Donor Retention Rate | C31: 70%+ | E31: % of prior-year major donors who renewed
A32: Close Rate (Gifts ÷ Proposals) | C32: 40–60% | E32: # gifts received ÷ # proposals submitted
A35: STATUS: ✅ On Track | ⚠️ Needs Attention | ❌ Off Track | 📋 Not Yet Measured (enter in column D)

Sheet Prospect Research Profiles
A1: PROSPECT RESEARCH PROFILES — MAJOR GIFT INTELLIGENCE
A2: Module 3: Major Gifts | Know your prospects deeply before investing cultivation time
A3: ℹ INSTRUCTIONS: Complete a research profile for every major gift prospect before cultivation begins. Tier 1 = all three Cs high; Tier 2 = two strong; Tier 3 = one strong or capacity only. All data is confidential — internal use only.
A4: ID / NAME | C4: THREE Cs QUALIFICATION | G4: FINANCIAL PROFILE | I4: PHILANTHROPIC HISTORY | K4: ORG RELATIONSHIP
A5: # | B5: Prospect Name | C5: Tier Rating | D5: Cap (H/M/L) | E5: Conn (H/M/L) | F5: Conc (H/M/L) | G5: Est. Capacity Range | H5: Proposed Ask ($) | I5: Known Gifts to Other Orgs | J5: Philanthropic Interests | K5: Org Connection & History | L5: Research Notes / Source
A6: 1 | B6: Eleanor & James Whitfield | C6: Tier 1 | D6: H | E6: H | F6: H | G6: $500K–$2M | H6: 250000 | I6: $50K City Arts Fund; $100K State U | J6: Education, arts, community | K6: 10-yr donors; 3 events; board intro | L6: Real estate $1.8M county records; 990s; peer screening
A7: 2 | B7: Dr. Marcus Chen | C7: Tier 1 | D7: H | E7: M | F7: H | G7: $1M–$5M | H7: 100000 | I7: $25K/yr Hospital Foundation | J7: Healthcare, youth mentorship | K7: Volunteer mentor 3 yrs; first gift $5K last year | L7: DonorSearch score 92; LinkedIn: retired surgeon
A8: 3 | B8: Patricia & Robert Goldstein | C8: Tier 2 | D8: H | E8: L | F8: M | G8: $2M+ | H8: 50000 | I8: Unknown — new prospect | J8: Environment, community | K8: Referred by board; no prior contact | L8: Property $2.4M; foundation 990 shows $30K+/yr giving
A9: 4 | B9: Hendricks Family Trust | C9: Tier 2 | D9: M | E9: H | F9: H | G9: $100K–$500K | H9: 25000 | I9: History unknown | J9: Children's services | K9: Long-time volunteers; never solicited | L9: Board peer screening; modest but loyal givers
A10: 5 | B10: William Park | C10: Tier 3 | D10: H | E10: L | F10: L | G10: $5M+ | H10: 500000 | I10: Hospital + university gifts | J10: Healthcare, higher ed | K10: No org connection — cold prospect | L10: iWave score A+; needs 2–3 yr cultivation investment
A52: PROSPECT TIER REFERENCE
A53: Tier 1 — Top Priority | B53: All three Cs strong. Assign to active personal cultivation NOW. Target 20–30 in portfolio at all times. Personal contact within 30 days.
A54: Tier 2 — Strong Potential | B54: Two of three Cs strong. Solid prospect needing development. Engage through events and communication. Elevate to Tier 1 as connection grows.
A55: Tier 3 — Watch List | B55: Capacity present but connection or concern weak. Long-term pipeline. Keep in newsletters; find warm introduction opportunities. Not yet ready for personal cultivation investment.

Sheet Moves Management
A1: MOVES MANAGEMENT TRACKER — MAJOR GIFT PORTFOLIO
A2: Module 3: Major Gifts | Every prospect. Every move. Every next step. No one goes 90 days without contact.
A3: ℹ INSTRUCTIONS: This is your primary working document. Update Stage after every significant interaction. The 90-Day Status column auto-flags overdue prospects. Review weekly and sort column K (Next Move Date) to prioritize actions.
A4: # | B4: Prospect Name | C4: Tier | D4: Stage | E4: Cap (H/M/L) | F4: Proposed Ask ($) | G4: Gift Purpose | H4: Priority (1–10) | I4: Last Move & Outcome | J4: Next Planned Move | K4: Next Move Date | L4: Assigned To | M4: 90-Day Status
A5: 1 | B5: Eleanor & James Whitfield | C5: Tier 1 | D5: Cultivation | E5: H | F5: 250000 | G5: Named Education Center | H5: 9 | I5: 04/20: Site visit — Ellie moved by student presentations. James asked about naming opportunities. | J5: ED lunch to discuss named gift proposal | K5: 05/15/2026 | L5: Executive Director | M5: ✅ ON TRACK
A6: 2 | B6: Dr. Marcus Chen | C6: Tier 1 | D6: Solicitation Ready | E6: H | F6: 100000 | G6: Youth Mentorship Endowment | H6: 10 | I6: 04/28: Discovery dinner. Ready to be asked. Said 'I want to do something significant this year.' | J6: Face-to-face ask — prepare written proposal first | K6: 05/10/2026 | L6: Dev. Director | M6: ✅ ON TRACK
A7: 3 | B7: Patricia & Robert Goldstein | C7: Tier 2 | D7: Cultivation | E7: H | F7: 50000 | G7: Environmental Program | H7: 6 | I7: 03/15: Board member email intro. Goldsteins expressed interest in a site visit. | J7: Invite to spring program tour | K7: 05/22/2026 | L7: Board Member (Gina) | M7: ✅ ON TRACK
A8: 4 | B8: Hendricks Family Trust | C8: Tier 2 | D8: Cultivation | E8: M | F8: 25000 | G8: Children's Services Fund | H8: 7 | I8: 04/05: Volunteer event conversation with Tom H. about program expansion. | J8: Thank-you call from ED + personalized impact update | K8: 05/01/2026 | L8: Executive Director | M8: ✅ ON TRACK
A9: 5 | B9: William Park | C9: Tier 3 | D9: Research | E9: H | F9: 500000 | G9: Capital Campaign | H9: 3 | I9: 04/10: Initial wealth research complete. Score A+. No org connection found. | J9: Board peer screening — identify connection to Park | K9: 06/01/2026 | L9: Dev. Director | M9: ✅ ON TRACK
A10: 6 | B10: Sandra & Leo Morales | C10: Tier 1 | D10: Stewardship | E10: H | F10: 75000 | G10: Scholarship Fund | H10: 8 | I10: 03/01: Gift of $75K received. Named scholarship established. Immediate thank-you from ED. | J10: 6-month impact report — introduce to first scholarship recipient | K10: 09/01/2026 | L10: Dev. Director | M10: —
A11: 7 | B11: Frank Nguyen | C11: Tier 2 | D11: Identification | E11: M | F11: 15000 | G11: Annual Fund Upgrade | H11: 5 | I11: 05/01: Flagged by peer screening. $3K annual donor for 6 years — never personally cultivated. | J11: Research: giving history, LinkedIn, property records | K11: 05/20/2026 | L11: Dev. Director | M11: ✅ ON TRACK
M12: =IF(K12="","",IF(K12<TODAY()-90,"⚠ OVERDUE",IF(K12<TODAY(),"📋 PAST DUE",IF(K12<=TODAY()+14,"🔔 DUE SOON","✅ ON TRACK"))))
M13: =IF(K13="","",IF(K13<TODAY()-90,"⚠ OVERDUE",IF(K13<TODAY(),"📋 PAST DUE",IF(K13<=TODAY()+14,"🔔 DUE SOON","✅ ON TRACK"))))
M14: =IF(K14="","",IF(K14<TODAY()-90,"⚠ OVERDUE",IF(K14<TODAY(),"📋 PAST DUE",IF(K14<=TODAY()+14,"🔔 DUE SOON","✅ ON TRACK"))))
M15: =IF(K15="","",IF(K15<TODAY()-90,"⚠ OVERDUE",IF(K15<TODAY(),"📋 PAST DUE",IF(K15<=TODAY()+14,"🔔 DUE SOON","✅ ON TRACK"))))
M16: =IF(K16="","",IF(K16<TODAY()-90,"⚠ OVERDUE",IF(K16<TODAY(),"📋 PAST DUE",IF(K16<=TODAY()+14,"🔔 DUE SOON","✅ ON TRACK"))))
M17: =IF(K17="","",IF(K17<TODAY()-90,"⚠ OVERDUE",IF(K17<TODAY(),"📋 PAST DUE",IF(K17<=TODAY()+14,"🔔 DUE SOON","✅ ON TRACK"))))
M18: =IF(K18="","",IF(K18<TODAY()-90,"⚠ OVERDUE",IF(K18<TODAY(),"📋 PAST DUE",IF(K18<=TODAY()+14,"🔔 DUE SOON","✅ ON TRACK"))))
M19: =IF(K19="","",IF(K19<TODAY()-90,"⚠ OVERDUE",IF(K19<TODAY(),"📋 PAST DUE",IF(K19<=TODAY()+14,"🔔 DUE SOON","✅ ON TRACK"))))
M20: =IF(K20="","",IF(K20<TODAY()-90,"⚠ OVERDUE",IF(K20<TODAY(),"📋 PAST DUE",IF(K20<=TODAY()+14,"🔔 DUE SOON","✅ ON TRACK"))))
M21: =IF(K21="","",IF(K21<TODAY()-90,"⚠ OVERDUE",IF(K21<TODAY(),"📋 PAST DUE",IF(K21<=TODAY()+14,"🔔 DUE SOON","✅ ON TRACK"))))
M22: =IF(K22="","",IF(K22<TODAY()-90,"⚠ OVERDUE",IF(K22<TODAY(),"📋 PAST DUE",IF(K22<=TODAY()+14,"🔔 DUE SOON","✅ ON TRACK"))))
M23: =IF(K23="","",IF(K23<TODAY()-90,"⚠ OVERDUE",IF(K23<TODAY(),"📋 PAST DUE",IF(K23<=TODAY()+14,"🔔 DUE SOON","✅ ON TRACK"))))
... M99: =IF(K99="","",IF(K99<TODAY()-90,"⚠ OVERDUE",IF(K99<TODAY(),"📋 PAST DUE",IF(K99<=TODAY()+14,"🔔 DUE SOON","✅ ON TRACK"))))
A101: STAGE REFERENCE
A102: Identification | B102: Prospect identified; research not started. Assign to portfolio immediately.
A103: Research | B103: Background research underway. Complete before any personal outreach.
A104: Cultivation | B104: Active moves being executed. No prospect should go 90 days without a documented contact.
A105: Solicitation Ready | B105: Cultivation complete; readiness confirmed. Plan and execute ask within 30 days.
A106: Proposal Submitted | B106: Formal ask made. Follow up within 1 week, then every 2–3 weeks until decision.
A107: Gift Received | B107: Gift closed. Execute immediate acknowledgment and transition to Stewardship.
A108: Stewardship | B108: Post-gift stewardship active. 4–6 personal touches per year. Begin renewal cultivation at 6–12 months.
A109: Declined | B109: Ask declined. Thank graciously. Continue respectful stewardship. Re-evaluate in 12 months.

Sheet Proposal Tracker
A1: MAJOR GIFT PROPOSAL TRACKER
A2: Module 3: Major Gifts | Track every formal ask from preparation through final outcome
A3: ℹ INSTRUCTIONS: Log every formal major gift solicitation. A proposal is any written or verbal ask at or above your major gift threshold. Proposals without a documented follow-up plan are the most common reason major gifts are lost.
A4: Total Proposals: | B4: =COUNTA(C6:C205)-COUNTBLANK(C6:C205) -> -192 | C4: Total Asked ($): | D4: =SUM(E6:E205) -> 450000 | E4: Total Closed ($): | F4: =SUMIF(G6:G205,"Gift Received",F6:F205) -> 85000 | G4: Close Rate: | H4: =IF(COUNTA(C6:C205)-COUNTBLANK(C6:C205)=0,"-",COUNTIF(G6:G205,"Gift Received")/(COUNTA(C6:C205)-COUNTBLANK(C6:C205))) -> -0.010416667 | I4: Pending: | J4: =COUNTIF(G6:G205,"Submitted")+COUNTIF(G6:G205,"Under Consideration") -> 3
A5: # | B5: Prospect Name | C5: Proposal Date | D5: Method | E5: Amount Requested ($) | F5: Actual Gift Received ($) | G5: Status | H5: Follow-Up Deadline | I5: Decision Date | J5: Assigned Solicitor | K5: Next Steps / Notes
A6: 1 | B6: Dr. Marcus Chen | C6: 05/10/2026 | D6: Face-to-Face | E6: 100000 | F6: 0 | G6: Submitted | H6: 05/17/2026 | J6: Dev. Director | K6: Asked at dinner — positive. Follow up 5/17.
A7: 2 | B7: Eleanor & James Whitfield | C7: 05/20/2026 | D7: Face-to-Face | E7: 250000 | F7: 0 | G7: Under Consideration | H7: 06/03/2026 | J7: Executive Director | K7: Named gift proposal delivered. Reviewing with family attorney.
A8: 3 | B8: Sandra & Leo Morales | C8: 02/28/2026 | D8: Face-to-Face | E8: 75000 | F8: 75000 | G8: Gift Received | I8: 03/01/2026 | J8: Executive Director | K8: Gift closed! Named scholarship established. Stewardship active.
A9: 4 | B9: Board Referral Prospect | C9: 04/01/2026 | D9: Written Proposal | E9: 25000 | F9: 10000 | G9: Gift Received | I9: 04/15/2026 | J9: Board Member | K9: Accepted at lower amount ($10K). Strong upgrade candidate.
A10: 5 | B10: Patricia & Robert Goldstein | E10: 50000 | F10: 0 | G10: Submitted | J10: Dev. Director | K10: Site visit needed before formal ask — in progress.
A207: PROPOSAL STATUS REFERENCE
A208: Submitted | B208: Ask made; no response yet. Follow up within 1 week.
A209: Under Consideration | B209: Donor is reviewing. Follow up every 2–3 weeks.
A210: Gift Received | B210: Gift closed. Begin stewardship immediately.
A211: Pledge Received | B211: Multi-year pledge committed. Document payment schedule.
A212: Declined | B212: Declined this cycle. Thank graciously; re-evaluate in 12 months.
A213: Withdrawn | B213: Proposal withdrawn. Re-approach when timing improves.

Sheet Stewardship Plans
A1: MAJOR DONOR STEWARDSHIP PLANS — 12-MONTH TOUCHPOINT CALENDAR
A2: Module 3: Major Gifts | Every major donor deserves a written plan. Target: 6–10 personal touches per year.
A3: ℹ INSTRUCTIONS: Add every major donor. Plan touchpoints month by month. Mark 'Done ✓' as completed. Aim for 6–10 touches annually. Immediate post-gift sequence: 24-hr call → personal note within 1 week → formal acknowledgment within 2 weeks.
A4: Major Donor Name | B4: Gift ($) | C4: Gift Date | D4: Priority Notes | E4: Jan | F4: Feb | G4: Mar | H4: Apr | I4: May | J4: Jun | K4: Jul | L4: Aug | M4: Sep | N4: Oct | O4: Nov | P4: Dec
A5: Sandra & Leo Morales | B5: 75000 | C5: Mar 2026 | D5: Named scholarship — HIGH priority. Planned gift potential. | E5: 24-hr Thank-You Call | F5: Formal Ack. Letter | G5: Scholar ship Selection | H5: Impact Update | J5: Site Visit: Meet Scholar | L5: Mid-Year Report | M5: Annual Report | O5: Renewal Cultivation | P5: Renewal Ask?
A6: Eleanor & James Whitfield | B6: 250000 | C6: Pending | D6: Named Education Center — transformational gift in progress. | E6: Cultivation Mtg | F6: Proposal Delivered | H6: Follow-Up Meeting | I6: Site Visit | K6: Impact Update | M6: Annual Report | N6: Board Lunch | O6: Renewal Convo
A7: Dr. Marcus Chen | B7: 100000 | C7: Pending | D7: Youth endowment ask pending May 2026. | E7: Discovery Dinner | I7: Ask Meeting | J7: Post-Ask Note | K7: Impact Update | M7: Event Invite | O7: Renewal Convo
A8: Anonymous Board Gift | B8: 10000 | C8: Apr 2026 | D8: First major gift — upgrade path to $25K in 2027. | F8: Thank-You Call | G8: Formal Ack. | I8: Impact Update | K8: Event Invite | M8: Annual Report | O8: Phone Check-In | P8: Renewal Ask
A9: Hendricks Family Trust | B9: 25000 | C9: Pending | D9: Volunteer-to-donor path — first ask upcoming. | G9: Vol. Recognition | H9: Discovery Call | J9: Impact Update | L9: Event Invite | O9: Cultivation Call | P9: Ask?
A46: MAJOR DONOR STEWARDSHIP SEQUENCE — FIRST 12 MONTHS POST-GIFT
A47: Within 24–48 hrs | B47: Personal phone call from the Executive Director or MGO. Warm and brief — pure appreciation, no agenda.
A48: Within 1 week | B48: Handwritten personal note from the ED. 3–4 sentences. Specific to this donor and this gift.
A49: Within 2 weeks | B49: Formal IRS-compliant acknowledgment letter. Warm and impact-focused — never a form letter.
A50: Month 2–3 | B50: Personalized impact update — a specific story or photo showing the gift at work. Not a newsletter.
A51: Month 4–5 | B51: Personal touchpoint: site visit, program introduction, or exclusive event invitation.
A52: Month 6 | B52: Mid-year impact report specific to their gift's purpose (named fund update, scholarship selection, program outcome).
A53: Month 7–8 | B53: Personal check-in — no ask. Share a news item or recognition related to their interests.
A54: Month 9–10 | B54: Annual report and appropriate recognition (with consent). Board or leadership engagement.
A55: Month 11 | B55: Soft cultivation conversation — listen, learn, and explore their evolving philanthropic priorities.
A56: Month 12 | B56: Renewal solicitation — framed as continuing and growing their impact, not a routine annual ask.
A57: 18–24 months+ | B57: For deeply committed donors: gentle, unhurried conversations about legacy and planned giving.

Sheet Portfolio Review
A1: MAJOR GIFT PORTFOLIO REVIEW CHECKLIST
A2: Module 3: Major Gifts | Review monthly (quarterly minimum) to keep every prospect advancing
A3: ℹ INSTRUCTIONS: Complete at each portfolio review. Use these questions to drive productive conversations with your ED, board, or development team. Update the Moves Management Tracker immediately after each review session.
A4: REVIEW SESSION DETAILS
A5: Review Date: | D5: Reviewer(s):
A6: Period Covered: | D6: Portfolio Size (# prospects):
A8: PIPELINE HEALTH
A9: Review Question | B9: Yes / No / Partial | C9: Names / Notes
A10: Are all Tier 1 prospects being contacted at least once every 60 days?
A11: Does every active cultivation prospect have a documented next move with a specific date and owner?
A12: Which prospects have gone 90+ days without a meaningful move? (Name them below)
A13: Which prospects are showing readiness signals and should move to Solicitation Ready?
A14: Which prospects are stalled despite repeated effort and should be de-prioritized to Tier 3?
A15: Are proposed ask amounts still accurate given what we have learned in cultivation?
A16: Do we have any prospects ready to be asked this month — and is the ask scheduled?
A18: PORTFOLIO ADDITIONS & EXITS
A19: Review Question | B19: Yes / No / Partial | C19: Names / Notes
A20: How many prospects were exited (gift received or declined) this period?
A21: Which Tier 3 prospects should be elevated to Tier 2 or Tier 1 based on recent engagement?
A22: Did any board members identify new prospects? Who will research and follow up?
A23: Are there lapsed major donors who should re-enter active cultivation?
A24: Are we maintaining the right portfolio size (20–50 Tier 1 prospects per MGO)?
A26: SOLICITATION PIPELINE
A27: Review Question | B27: Yes / No / Partial | C27: Names / Notes
A28: How many proposals are currently outstanding? What is the combined dollar amount?
A29: Which outstanding proposals are overdue for a follow-up and need immediate attention?
A30: Are there Solicitation Ready prospects with no scheduled ask date? Who makes the ask and when?
A31: For any declined proposals: what did we learn, and what is the re-engagement plan?
A33: STEWARDSHIP REVIEW
A34: Review Question | B34: Yes / No / Partial | C34: Names / Notes
A35: Which major donors have not received a personal touchpoint in 60+ days?
A36: Are all post-gift stewardship plans being executed on schedule?
A37: Which donors are approaching 12 months post-gift and need a renewal cultivation plan?
A38: Is there a donor ready for a planned giving conversation? Who initiates it?
A40: ACTION ITEMS
A41: Action Item | B41: Assigned To | C41: Due Date | D41: Notes
A42: Action Item 1:
A43: Action Item 2:
A44: Action Item 3:
A45: Action Item 4:
...

Sheet 80-20 Revenue Analysis
A1: 80/20 REVENUE ANALYSIS — DONOR GIVING CONCENTRATION
A2: Module 3: Major Gifts | Understand concentration to prioritize cultivation and mitigate risk
A3: ℹ INSTRUCTIONS: Enter each donor's giving in the ledger below (sorted largest to smallest). Summary metrics auto-calculate. Run annually and share with your board development committee. Blue cells = data entry required.
A4: CONCENTRATION SUMMARY
A5: Total Donors (this fiscal year) | F5: Enter total unique donors at all levels
A6: Total Individual Giving Revenue ($) | F6: Enter total individual giving revenue
A7: Major Gift Threshold ($) | F7: Enter your org's major gift threshold
A8: # of Major Donors | B8: =COUNTIF(C9:C208,">="&B6) -> 1 | F8: Auto-calc from ledger
A9: Total Major Gift Revenue ($) | B9: =SUMIF(C9:C208,">="&B6,C9:C208) -> 0 | F9: Auto-calc from ledger
A10: Major Gifts % of Total Revenue | B10: =IF(B5=0,"-",B8/B5) -> - | F10: Auto-calc
A11: Major Donors % of Total Donors | B11: =IF(B4=0,"-",B7/B4) -> - | F11: Auto-calc
A12: Top 10 Donors Total Giving ($) | B12: =SUM(C9:C18) -> 85000 | F12: Auto-calc (requires table sorted largest→smallest)
A13: Top 10 as % of Total Revenue | B13: =IF(B5=0,"-",B12/B5) -> - | F13: Auto-calc
A15: DONOR GIVING LEDGER (Sort column C largest → smallest for accurate cumulative calculations)
A16: Donor Name | B16: Prospect Tier | C16: Gift Amount This Year ($) | D16: Cumulative Total ($) | E16: Cumulative % of Revenue | F16: YOY Change (+/-) | G16: Notes / Stewardship Flag
A17: Sandra & Leo Morales | B17: Tier 1 | C17: 75000 | D17: =SUM($C$17:C17) -> 75000 | E17: =IF($B$5=0,"-",D17/$B$5) -> - | F17: New | G17: Gift closed Mar 2026
A18: Anonymous Board Donor | B18: Tier 1 | C18: 10000 | D18: =SUM($C$17:C18) -> 85000 | E18: =IF($B$5=0,"-",D18/$B$5) -> - | F18: +25% | G18: Upgrade from $8K
A19: Dr. Marcus Chen | B19: Tier 1 | D19: =SUM($C$17:C19) -> 85000 | E19: =IF($B$5=0,"-",D19/$B$5) -> - | F19: New | G19: Gift pending May 2026
A20: Eleanor & James Whitfield | B20: Tier 1 | D20: =SUM($C$17:C20) -> 85000 | E20: =IF($B$5=0,"-",D20/$B$5) -> - | F20: New | G20: Gift pending — proposal delivered
A21: The Hendricks Family | B21: Tier 2 | D21: =SUM($C$17:C21) -> 85000 | E21: =IF($B$5=0,"-",D21/$B$5) -> - | F21: New | G21: First major gift pending
A22: James Thompson | B22: Mid-Level | C22: 2500 | D22: =SUM($C$17:C22) -> 87500 | E22: =IF($B$5=0,"-",D22/$B$5) -> - | F22: 0% | G22: Renewed at same level
A23: Susan Park | B23: Mid-Level | C23: 1500 | D23: =SUM($C$17:C23) -> 89000 | E23: =IF($B$5=0,"-",D23/$B$5) -> - | F23: -25% | G23: Downgraded — personal follow-up needed
A24: Maria Garcia | B24: Mid-Level | D24: =SUM($C$17:C24) -> 89000 | E24: =IF($B$5=0,"-",D24/$B$5) -> - | F24: New | G24: Cultivation in progress
A25: Robert Lee | B25: Annual | C25: 750 | D25: =SUM($C$17:C25) -> 89750 | E25: =IF($B$5=0,"-",D25/$B$5) -> - | F25: 0% | G25: Consistent annual donor
A26: Patricia Williams | B26: Annual | C26: 500 | D26: =SUM($C$17:C26) -> 90250 | E26: =IF($B$5=0,"-",D26/$B$5) -> - | F26: New | G26: First-time donor
D27: =SUM($C$17:C27) -> 90250 | E27: =IF($B$5=0,"-",D27/$B$5) -> -
D28: =SUM($C$17:C28) -> 90250 | E28: =IF($B$5=0,"-",D28/$B$5) -> -
D29: =SUM($C$17:C29) -> 90250 | E29: =IF($B$5=0,"-",D29/$B$5) -> -
D30: =SUM($C$17:C30) -> 90250 | E30: =IF($B$5=0,"-",D30/$B$5) -> -
D31: =SUM($C$17:C31) -> 90250 | E31: =IF($B$5=0,"-",D31/$B$5) -> -
D32: =SUM($C$17:C32) -> 90250 | E32: =IF($B$5=0,"-",D32/$B$5) -> -
D33: =SUM($C$17:C33) -> 90250 | E33: =IF($B$5=0,"-",D33/$B$5) -> -
D34: =SUM($C$17:C34) -> 90250 | E34: =IF($B$5=0,"-",D34/$B$5) -> -
D35: =SUM($C$17:C35) -> 90250 | E35: =IF($B$5=0,"-",D35/$B$5) -> -
D36: =SUM($C$17:C36) -> 90250 | E36: =IF($B$5=0,"-",D36/$B$5) -> -
D37: =SUM($C$17:C37) -> 90250 | E37: =IF($B$5=0,"-",D37/$B$5) -> -
D38: =SUM($C$17:C38) -> 90250 | E38: =IF($B$5=0,"-",D38/$B$5) -> -
... D206: =SUM($C$17:C206) -> 90250 | E206: =IF($B$5=0,"-",D206/$B$5) -> -
A208: WHAT YOUR NUMBERS MEAN
A209: • If your top 10 donors represent 60–80% of total individual revenue, you have healthy major gift concentration — and a significant vulnerability. Losing one top donor could be catastrophic.
...
